Traceback (most recent call last):
  File "/usr/local/lib/python3.12/site-packages/jupyter_core/utils/__init__.py", line 154, in wrapped
    asyncio.get_running_loop()
RuntimeError: no running event loop

During handling of the above exception, another exception occurred:

Traceback (most recent call last):
  File "/usr/local/lib/python3.12/site-packages/jupyter_cache/executors/utils.py", line 58, in single_nb_execution
    executenb(
  File "/usr/local/lib/python3.12/site-packages/nbclient/client.py", line 1319, in execute
    return NotebookClient(nb=nb, resources=resources, km=km, **kwargs).execute()
           ^^^^^^^^^^^^^^^^^^^^^^^^^^^^^^^^^^^^^^^^^^^^^^^^^^^^^^^^^^^^^^^^^^^^^
  File "/usr/local/lib/python3.12/site-packages/jupyter_core/utils/__init__.py", line 158, in wrapped
    return loop.run_until_complete(inner)
           ^^^^^^^^^^^^^^^^^^^^^^^^^^^^^^
  File "/usr/local/lib/python3.12/asyncio/base_events.py", line 691, in run_until_complete
    return future.result()
           ^^^^^^^^^^^^^^^
  File "/usr/local/lib/python3.12/site-packages/nbclient/client.py", line 709, in async_execute
    await self.async_execute_cell(
  File "/usr/local/lib/python3.12/site-packages/nbclient/client.py", line 1062, in async_execute_cell
    await self._check_raise_for_error(cell, cell_index, exec_reply)
  File "/usr/local/lib/python3.12/site-packages/nbclient/client.py", line 918, in _check_raise_for_error
    raise CellExecutionError.from_cell_and_msg(cell, exec_reply_content)
nbclient.exceptions.CellExecutionError: An error occurred while executing the following cell:
------------------
multi_exps1_reades = experiment_hadamard.multiRead(
    save_location=".",
    summoner_name="qurrent.hadamard_test.001",
)
------------------

----- stdout -----
| Retrieve qurrent.hadamard_test.001...
| at: qurrent.hadamard_test.001
------------------

[31m---------------------------------------------------------------------------[39m
[31mRemoteTraceback[39m                           Traceback (most recent call last)
[31mRemoteTraceback[39m: 
"""
Traceback (most recent call last):
  File "/usr/local/lib/python3.12/multiprocessing/pool.py", line 125, in worker
    result = (True, func(*args, **kwds))
                    ^^^^^^^^^^^^^^^^^^^
  File "/usr/local/lib/python3.12/site-packages/qurry/qurrium/experiment/experiment.py", line 1365, in _read_core_multiprocess
    return cls._read_core(exp_id, file_index, save_location, encoding)
           ^^^^^^^^^^^^^^^^^^^^^^^^^^^^^^^^^^^^^^^^^^^^^^^^^^^^^^^^^^^
  File "/usr/local/lib/python3.12/site-packages/qurry/qurrium/experiment/experiment.py", line 1323, in _read_core
    exp_instance = cls(
                   ^^^^
  File "/usr/local/lib/python3.12/site-packages/qurry/qurrium/experiment/experiment.py", line 174, in __init__
    self.commons = Commonparams(**commons_dealing(common_parsed, self.analysis_instance))
                   ^^^^^^^^^^^^^^^^^^^^^^^^^^^^^^^^^^^^^^^^^^^^^^^^^^^^^^^^^^^^^^^^^^^^^^
TypeError: Commonparams.__new__() missing 2 required positional arguments: 'filename' and 'files'
"""

The above exception was the direct cause of the following exception:

[31mTypeError[39m                                 Traceback (most recent call last)
[36mCell[39m[36m [39m[32mIn[16][39m[32m, line 1[39m
[32m----> [39m[32m1[39m multi_exps1_reades = [43mexperiment_hadamard[49m[43m.[49m[43mmultiRead[49m[43m([49m
[32m      2[39m [43m    [49m[43msave_location[49m[43m=[49m[33;43m"[39;49m[33;43m.[39;49m[33;43m"[39;49m[43m,[49m
[32m      3[39m [43m    [49m[43msummoner_name[49m[43m=[49m[33;43m"[39;49m[33;43mqurrent.hadamard_test.001[39;49m[33;43m"[39;49m[43m,[49m
[32m      4[39m [43m)[49m

[36mFile [39m[32m/usr/local/lib/python3.12/site-packages/qurry/qurrium/qurrium.py:823[39m, in [36mQurriumPrototype.multiRead[39m[34m(self, summoner_name, save_location, reload, read_from_tarfile)[39m
[32m    818[39m [38;5;28;01melif[39;00m [38;5;28mlen[39m(filtered_summoner_id_names) > [32m1[39m:
[32m    819[39m     [38;5;28;01mraise[39;00m [38;5;167;01mValueError[39;00m(
[32m    820[39m         [33mf[39m[33m"[39m[33mMultiple multimanager found for [39m[33m'[39m[38;5;132;01m{[39;00msummoner_name[38;5;132;01m}[39;00m[33m'[39m[33m: [39m[38;5;132;01m{[39;00mfiltered_summoner_id_names[38;5;132;01m}[39;00m[33m.[39m[33m"[39m
[32m    821[39m     )
[32m--> [39m[32m823[39m current_multimanager = [43mMultiManager[49m[43m.[49m[43mread[49m[43m([49m
[32m    824[39m [43m    [49m[43msummoner_name[49m[43m=[49m[43msummoner_name[49m[43m,[49m
[32m    825[39m [43m    [49m[43mexperiment_instance[49m[43m=[49m[38;5;28;43mself[39;49m[43m.[49m[43mexperiment_instance[49m[43m,[49m
[32m    826[39m [43m    [49m[43msave_location[49m[43m=[49m[43msave_location[49m[43m,[49m
[32m    827[39m [43m    [49m[43mis_read_or_retrieve[49m[43m=[49m[38;5;28;43;01mTrue[39;49;00m[43m,[49m
[32m    828[39m [43m    [49m[43mread_from_tarfile[49m[43m=[49m[43mread_from_tarfile[49m[43m,[49m
[32m    829[39m [43m[49m[43m)[49m
[32m    830[39m [38;5;28mself[39m.multimanagers[current_multimanager.summoner_id] = current_multimanager
[32m    832[39m [38;5;28;01mreturn[39;00m current_multimanager.multicommons.summoner_id

[36mFile [39m[32m/usr/local/lib/python3.12/site-packages/qurry/qurrium/multimanager/multimanager.py:611[39m, in [36mMultiManager.read[39m[34m(cls, summoner_name, experiment_instance, save_location, is_read_or_retrieve, read_from_tarfile, encoding)[39m
[32m    608[39m                 [38;5;28;01mif[39;00m path.exists():
[32m    609[39m                     path.unlink()
[32m--> [39m[32m611[39m reading_results: [38;5;28mlist[39m[_E] = [43mexperiment_instance[49m[43m.[49m[43mread[49m[43m([49m[43m  [49m[38;5;66;43;03m# type: ignore[39;49;00m
[32m    612[39m [43m    [49m[43msave_location[49m[43m=[49m[43mcurrent_multimanager[49m[43m.[49m[43mmulticommons[49m[43m.[49m[43msave_location[49m[43m,[49m
[32m    613[39m [43m    [49m[43mname_or_id[49m[43m=[49m[43mcurrent_multimanager[49m[43m.[49m[43mmulticommons[49m[43m.[49m[43msummoner_name[49m[43m,[49m
[32m    614[39m [43m[49m[43m)[49m
[32m    615[39m [38;5;28;01mfor[39;00m read_exps [38;5;129;01min[39;00m reading_results:
[32m    616[39m     current_multimanager.exps[read_exps.commons.exp_id] = read_exps

[36mFile [39m[32m/usr/local/lib/python3.12/site-packages/qurry/qurrium/experiment/experiment.py:1444[39m, in [36mExperimentPrototype.read[39m[34m(cls, name_or_id, save_location, encoding)[39m
[32m   1427[39m [38;5;28;01mwith[39;00m reading_pool [38;5;28;01mas[39;00m pool:
[32m   1428[39m     exps_iterable = qurry_progressbar(
[32m   1429[39m         pool.imap_unordered(
[32m   1430[39m             [38;5;28mcls[39m._read_core_multiprocess,
[32m   (...)[39m[32m   1442[39m         desc=[33mf[39m[33m"[39m[33mLoading [39m[38;5;132;01m{[39;00mnum_exps[38;5;132;01m}[39;00m[33m experiments ...[39m[33m"[39m,
[32m   1443[39m     )
[32m-> [39m[32m1444[39m     exps = [38;5;28;43mlist[39;49m[43m([49m[43mexps_iterable[49m[43m)[49m
[32m   1446[39m [38;5;28;01mreturn[39;00m exps

[36mFile [39m[32m/usr/local/lib/python3.12/site-packages/tqdm/notebook.py:250[39m, in [36mtqdm_notebook.__iter__[39m[34m(self)[39m
[32m    248[39m [38;5;28;01mtry[39;00m:
[32m    249[39m     it = [38;5;28msuper[39m().[34m__iter__[39m()
[32m--> [39m[32m250[39m [43m    [49m[38;5;28;43;01mfor[39;49;00m[43m [49m[43mobj[49m[43m [49m[38;5;129;43;01min[39;49;00m[43m [49m[43mit[49m[43m:[49m
[32m    251[39m [43m        [49m[38;5;66;43;03m# return super(tqdm...) will not catch exception[39;49;00m
[32m    252[39m [43m        [49m[38;5;28;43;01myield[39;49;00m[43m [49m[43mobj[49m
[32m    253[39m [38;5;66;03m# NB: except ... [ as ...] breaks IPython async KeyboardInterrupt[39;00m

[36mFile [39m[32m/usr/local/lib/python3.12/site-packages/tqdm/std.py:1181[39m, in [36mtqdm.__iter__[39m[34m(self)[39m
[32m   1178[39m time = [38;5;28mself[39m._time
[32m   1180[39m [38;5;28;01mtry[39;00m:
[32m-> [39m[32m1181[39m [43m    [49m[38;5;28;43;01mfor[39;49;00m[43m [49m[43mobj[49m[43m [49m[38;5;129;43;01min[39;49;00m[43m [49m[43miterable[49m[43m:[49m
[32m   1182[39m [43m        [49m[38;5;28;43;01myield[39;49;00m[43m [49m[43mobj[49m
[32m   1183[39m [43m        [49m[38;5;66;43;03m# Update and possibly print the progressbar.[39;49;00m
[32m   1184[39m [43m        [49m[38;5;66;43;03m# Note: does not call self.update(1) for speed optimisation.[39;49;00m

[36mFile [39m[32m/usr/local/lib/python3.12/multiprocessing/pool.py:873[39m, in [36mIMapIterator.next[39m[34m(self, timeout)[39m
[32m    871[39m [38;5;28;01mif[39;00m success:
[32m    872[39m     [38;5;28;01mreturn[39;00m value
[32m--> [39m[32m873[39m [38;5;28;01mraise[39;00m value

[31mTypeError[39m: Commonparams.__new__() missing 2 required positional arguments: 'filename' and 'files'

