Traceback (most recent call last):
  File "/home/nccu/uv-python-venv/quantumsphere13/lib/python3.13/site-packages/jupyter_core/utils/__init__.py", line 154, in wrapped
    asyncio.get_running_loop()
    ~~~~~~~~~~~~~~~~~~~~~~~~^^
RuntimeError: no running event loop

During handling of the above exception, another exception occurred:

Traceback (most recent call last):
  File "/home/nccu/uv-python-venv/quantumsphere13/lib/python3.13/site-packages/jupyter_cache/executors/utils.py", line 58, in single_nb_execution
    executenb(
    ~~~~~~~~~^
        nb,
        ^^^
    ...<4 lines>...
        **kwargs,
        ^^^^^^^^^
    )
    ^
  File "/home/nccu/uv-python-venv/quantumsphere13/lib/python3.13/site-packages/nbclient/client.py", line 1319, in execute
    return NotebookClient(nb=nb, resources=resources, km=km, **kwargs).execute()
           ~~~~~~~~~~~~~~~~~~~~~~~~~~~~~~~~~~~~~~~~~~~~~~~~~~~~~~~~~~~~~~~~~~~^^
  File "/home/nccu/uv-python-venv/quantumsphere13/lib/python3.13/site-packages/jupyter_core/utils/__init__.py", line 158, in wrapped
    return loop.run_until_complete(inner)
           ~~~~~~~~~~~~~~~~~~~~~~~^^^^^^^
  File "/home/nccu/.local/share/uv/python/cpython-3.13.3-linux-x86_64-gnu/lib/python3.13/asyncio/base_events.py", line 719, in run_until_complete
    return future.result()
           ~~~~~~~~~~~~~^^
  File "/home/nccu/uv-python-venv/quantumsphere13/lib/python3.13/site-packages/nbclient/client.py", line 709, in async_execute
    await self.async_execute_cell(
        cell, index, execution_count=self.code_cells_executed + 1
    )
  File "/home/nccu/uv-python-venv/quantumsphere13/lib/python3.13/site-packages/nbclient/client.py", line 1062, in async_execute_cell
    await self._check_raise_for_error(cell, cell_index, exec_reply)
  File "/home/nccu/uv-python-venv/quantumsphere13/lib/python3.13/site-packages/nbclient/client.py", line 918, in _check_raise_for_error
    raise CellExecutionError.from_cell_and_msg(cell, exec_reply_content)
nbclient.exceptions.CellExecutionError: An error occurred while executing the following cell:
------------------
from qurry.qurrium.wavesqurry.arguments import WavesExecuterMeasureArgs
------------------


[31m---------------------------------------------------------------------------[39m
[31mTypeError[39m                                 Traceback (most recent call last)
[36mCell[39m[36m [39m[32mIn[3][39m[32m, line 1[39m
[32m----> [39m[32m1[39m [38;5;28;01mfrom[39;00m[38;5;250m [39m[34;01mqurry[39;00m[34;01m.[39;00m[34;01mqurrium[39;00m[34;01m.[39;00m[34;01mwavesqurry[39;00m[34;01m.[39;00m[34;01marguments[39;00m[38;5;250m [39m[38;5;28;01mimport[39;00m WavesExecuterMeasureArgs

[36mFile [39m[32m~/uv-python-venv/quantumsphere13/lib/python3.13/site-packages/qurry/qurrium/wavesqurry/__init__.py:8[39m
[32m      6[39m [38;5;28;01mfrom[39;00m[38;5;250m [39m[34;01m.[39;00m[34;01manalysis[39;00m[38;5;250m [39m[38;5;28;01mimport[39;00m WavesExecuterAnalysis
[32m      7[39m [38;5;28;01mfrom[39;00m[38;5;250m [39m[34;01m.[39;00m[34;01mexperiment[39;00m[38;5;250m [39m[38;5;28;01mimport[39;00m WavesExecuterExperiment
[32m----> [39m[32m8[39m [38;5;28;01mfrom[39;00m[38;5;250m [39m[34;01m.[39;00m[34;01mqurry[39;00m[38;5;250m [39m[38;5;28;01mimport[39;00m WavesExecuter

[36mFile [39m[32m~/uv-python-venv/quantumsphere13/lib/python3.13/site-packages/qurry/qurrium/wavesqurry/qurry.py:21[39m
[32m     17[39m [38;5;28;01mfrom[39;00m[38;5;250m [39m[34;01m.[39;00m[34;01m.[39;00m[34;01mqurrium[39;00m[38;5;250m [39m[38;5;28;01mimport[39;00m QurriumPrototype
[32m     18[39m [38;5;28;01mfrom[39;00m[38;5;250m [39m[34;01m.[39;00m[34;01m.[39;00m[34;01m.[39;00m[34;01mdeclare[39;00m[38;5;250m [39m[38;5;28;01mimport[39;00m BaseRunArgs, TranspileArgs, OutputArgs
[32m---> [39m[32m21[39m [38;5;28;01mclass[39;00m[38;5;250m [39m[34;01mWavesExecuter[39;00m([43mQurriumPrototype[49m[43m[[49m[43mWavesExecuterExperiment[49m[43m][49m):
[32m     22[39m [38;5;250m    [39m[33;03m"""The pending and retrieve executer for waves."""[39;00m
[32m     24[39m     [34m__name__[39m = [33m"[39m[33mWavesExecuter[39m[33m"[39m

[36mFile [39m[32m~/.local/share/uv/python/cpython-3.13.3-linux-x86_64-gnu/lib/python3.13/typing.py:432[39m, in [36m_tp_cache.<locals>.decorator.<locals>.inner[39m[34m(*args, **kwds)[39m
[32m    430[39m [38;5;28;01mexcept[39;00m [38;5;167;01mTypeError[39;00m:
[32m    431[39m     [38;5;28;01mpass[39;00m  [38;5;66;03m# All real errors (not unhashable args) are raised below.[39;00m
[32m--> [39m[32m432[39m [38;5;28;01mreturn[39;00m [43mfunc[49m[43m([49m[43m*[49m[43margs[49m[43m,[49m[43m [49m[43m*[49m[43m*[49m[43mkwds[49m[43m)[49m

[36mFile [39m[32m~/.local/share/uv/python/cpython-3.13.3-linux-x86_64-gnu/lib/python3.13/typing.py:1242[39m, in [36m_generic_class_getitem[39m[34m(cls, args)[39m
[32m   1240[39m     prepare = [38;5;28mgetattr[39m(param, [33m'[39m[33m__typing_prepare_subst__[39m[33m'[39m, [38;5;28;01mNone[39;00m)
[32m   1241[39m     [38;5;28;01mif[39;00m prepare [38;5;129;01mis[39;00m [38;5;129;01mnot[39;00m [38;5;28;01mNone[39;00m:
[32m-> [39m[32m1242[39m         args = [43mprepare[49m[43m([49m[38;5;28;43mcls[39;49m[43m,[49m[43m [49m[43margs[49m[43m)[49m
[32m   1243[39m _check_generic_specialization([38;5;28mcls[39m, args)
[32m   1245[39m new_args = []

[31mTypeError[39m: Too few arguments for <class 'qurry.qurrium.qurrium.QurriumPrototype'>; actual 1, expected at least 2

