Traceback (most recent call last):
  File "/usr/local/lib/python3.12/site-packages/jupyter_core/utils/__init__.py", line 154, in wrapped
    asyncio.get_running_loop()
RuntimeError: no running event loop

During handling of the above exception, another exception occurred:

Traceback (most recent call last):
  File "/usr/local/lib/python3.12/site-packages/jupyter_cache/executors/utils.py", line 58, in single_nb_execution
    executenb(
  File "/usr/local/lib/python3.12/site-packages/nbclient/client.py", line 1319, in execute
    return NotebookClient(nb=nb, resources=resources, km=km, **kwargs).execute()
           ^^^^^^^^^^^^^^^^^^^^^^^^^^^^^^^^^^^^^^^^^^^^^^^^^^^^^^^^^^^^^^^^^^^^^
  File "/usr/local/lib/python3.12/site-packages/jupyter_core/utils/__init__.py", line 158, in wrapped
    return loop.run_until_complete(inner)
           ^^^^^^^^^^^^^^^^^^^^^^^^^^^^^^
  File "/usr/local/lib/python3.12/asyncio/base_events.py", line 691, in run_until_complete
    return future.result()
           ^^^^^^^^^^^^^^^
  File "/usr/local/lib/python3.12/site-packages/nbclient/client.py", line 709, in async_execute
    await self.async_execute_cell(
  File "/usr/local/lib/python3.12/site-packages/nbclient/client.py", line 1062, in async_execute_cell
    await self._check_raise_for_error(cell, cell_index, exec_reply)
  File "/usr/local/lib/python3.12/site-packages/nbclient/client.py", line 918, in _check_raise_for_error
    raise CellExecutionError.from_cell_and_msg(cell, exec_reply_content)
nbclient.exceptions.CellExecutionError: An error occurred while executing the following cell:
------------------
main01, side_product01 = report01.export(jsonable=False)
# you need to set jsonable=False to get the raw data
# Otherwise, the data will be converted to JSON format,
# which 'expect_rho' will be a string instead of a numpy array

for k, v in main01.items():
    if k == "expect_rho":
        continue
    print(f"| {k}: {v}")
print("| shape of expect_rho:")
print(main01["expect_rho"].shape)
------------------


[31m---------------------------------------------------------------------------[39m
[31mTypeError[39m                                 Traceback (most recent call last)
[36mCell[39m[36m [39m[32mIn[9][39m[32m, line 1[39m
[32m----> [39m[32m1[39m main01, side_product01 = [43mreport01[49m[43m.[49m[43mexport[49m[43m([49m[43mjsonable[49m[43m=[49m[38;5;28;43;01mFalse[39;49;00m[43m)[49m
[32m      2[39m [38;5;66;03m# you need to set jsonable=False to get the raw data[39;00m
[32m      3[39m [38;5;66;03m# Otherwise, the data will be converted to JSON format,[39;00m
[32m      4[39m [38;5;66;03m# which 'expect_rho' will be a string instead of a numpy array[39;00m
[32m      6[39m [38;5;28;01mfor[39;00m k, v [38;5;129;01min[39;00m main01.items():

[31mTypeError[39m: AnalysisPrototype.export() got an unexpected keyword argument 'jsonable'

